<?xml version="1.0" ?>
<sdf version="1.9">
  <model name="petra_robot">
    <pose>0 0 0.1 0 0 0</pose> 
    <!-- Base Link -->
    <link name="base_link">
      <inertial>
        <mass>2.0</mass>
        <inertia>
          <ixx>0.01</ixx>
          <iyy>0.01</iyy>
          <izz>0.01</izz>
          <ixy>0.0</ixy>
          <ixz>0.0</ixz>
          <iyz>0.0</iyz>
        </inertia>
      </inertial>
      <visual name="base_visual">
        <geometry>
          <box>
            <size>0.4 0.3 0.08</size>
          </box>
        </geometry>
        <material>
          <ambient>1.0 1.0 0.0 1.0</ambient>
          <diffuse>1.0 1.0 0.0 1.0</diffuse>
        </material>
      </visual>
      <collision name="base_collision">
        <geometry>
          <box>
            <size>0.4 0.3 0.08</size>
          </box>
        </geometry>
      </collision>
    </link>

    <!-- Right Wheel -->
    <link name="right_wheel">
        <pose relative_to="base_link">0.1 -0.175 0 0 1.5708 1.5708</pose>   
      <inertial>
        <mass>1.0</mass>
        <inertia>
          <ixx>0.001</ixx>
          <iyy>0.001</iyy>
          <izz>0.001</izz>
        </inertia>
      </inertial>
      <visual name="right_wheel_visual">
        <geometry>
          <cylinder>
            <radius>0.08</radius>
            <length>0.05</length>
          </cylinder>
        </geometry>
        <material>
          <ambient>1.0 0.0 0.0 1.0</ambient>
          <diffuse>1.0 0.0 0.0 1.0</diffuse>
        </material>
      </visual>
      <collision name="right_wheel_collision">
        <geometry>
          <cylinder>
            <radius>0.08</radius>
            <length>0.05</length>
          </cylinder>
        </geometry>
      </collision>
    </link>

    <joint name="right_wheel_joint" type="revolute">
      <parent>base_link</parent>
      <child>right_wheel</child>
      <axis>
        <xyz>0 0 1</xyz>
            <limit>
                <lower>-1.79769e+308</lower>    
                <upper>1.79769e+308</upper>
            </limit>
      </axis>
      <!-- <pose>0.1 -0.175 0 0 1.5708 1.5708</pose> -->
    </joint>

    <!-- Left Wheel -->
    <link name="left_wheel">
      <pose relative_to="base_link">0.1 0.175 0 0 1.5708 1.5708</pose>   

      <inertial>
        <mass>1.0</mass>
        <inertia>
          <ixx>0.001</ixx>
          <iyy>0.001</iyy>
          <izz>0.001</izz>
        </inertia>
      </inertial>
      <visual name="left_wheel_visual">
        <geometry>
          <cylinder>
            <radius>0.08</radius>
            <length>0.05</length>
          </cylinder>
        </geometry>
        <material>
          <ambient>1.0 0.0 0.0 1.0</ambient>
          <diffuse>1.0 0.0 0.0 1.0</diffuse>
        </material>
      </visual>
      <collision name="left_wheel_collision">
        <geometry>
          <cylinder>
            <radius>0.08</radius>
            <length>0.05</length>
          </cylinder>
        </geometry>
      </collision>
    </link>
    <joint name="left_wheel_joint" type="revolute">
      <parent>base_link</parent>
      <child>left_wheel</child>
      <axis>
        <xyz>0 0 1</xyz>
            <limit>
                <lower>-1.79769e+308</lower>    
                <upper>1.79769e+308</upper>
            </limit>
      </axis>
      <!-- <pose>0.1 0.175 0 0 1.5708 1.5708</pose> -->
    </joint>

    <!-- Caster Wheel -->
    <link name="caster_wheel_link">
        <pose relative_to="base_link">-0.1 0 -0.06 0 0 0</pose>    

      <inertial>
        <mass>0.5</mass>
        <inertia>
          <ixx>0.001</ixx>
          <iyy>0.001</iyy>
          <izz>0.001</izz>
        </inertia>
      </inertial>
      <visual name="caster_wheel_visual">
        <geometry>
          <sphere>
            <radius>0.02</radius>
          </sphere>
        </geometry>
        <material>
          <ambient>1.0 0.0 0.0 1.0</ambient>
          <diffuse>1.0 0.0 0.0 1.0</diffuse>
        </material>
      </visual>
      <collision name="caster_wheel_collision">
        <geometry>
          <sphere>
            <radius>0.02</radius>
          </sphere>
        </geometry>
      </collision>
    </link>
    <joint name="caster_wheel_joint" type="revolute">
      <parent>base_link</parent>
      <child>caster_wheel_link</child>
    </joint>

    <!-- Lidar Base -->
    <!-- <link name="lidar_base_link">
      <inertial>
        <mass>0.5</mass>
        <inertia>
          <ixx>0.0008667</ixx>
          <iyy>0.0016</iyy>
          <izz>0.0017333</izz>
        </inertia>
      </inertial>
      <visual name="lidar_base_visual">
        <geometry>
          <box>
            <size>0.1 0.2 0.07</size>
          </box>
        </geometry>
        <material>
          <ambient>1.0 1.0 0.0 1.0</ambient>
          <diffuse>1.0 1.0 0.0 1.0</diffuse>
        </material>
      </visual>
      <collision name="lidar_base_collision">
        <geometry>
          <box>
            <size>0.2 0.2 0.07</size>
          </box>
        </geometry>
      </collision>
    </link>
    <joint name="lidar_base_joint" type="fixed">
      <parent>base_link</parent>
      <child>lidar_base_link</child>
      <pose>-0.1 0 0.06 0 0 0</pose>
    </joint> -->

    <!-- Lidar -->
    <!-- <link name="lidar_link">
      <inertial>
        <mass>0.5</mass>
        <inertia>
          <ixx>0.001</ixx>
          <iyy>0.001</iyy>
          <izz>0.001</izz>
        </inertia>
      </inertial>
      <visual name="lidar_visual">
        <geometry>
          <mesh>
            <uri>meshes/2d_lidar.STL</uri> 
          </mesh>
        </geometry>
        <material>
          <ambient>0.0 0.0 0.0 1.0</ambient>
          <diffuse>0.0 0.0 0.0 1.0</diffuse>
        </material>
      </visual>
      <collision name="lidar_collision">
        <geometry>
          <mesh>
            <uri>meshes/2d_lidar.STL</uri> 
          </mesh>
        </geometry>
      </collision>
    </link> -->
    <!-- <joint name="lidar_joint" type="fixed">
      <parent>lidar_base_link</parent>
      <child>lidar_link</child>
      <pose>0 0 0.065 0 0 0</pose>
    </joint> -->
  </model>
</sdf>
            <!-- <uri>package://petra_robot/meshes/2d_lidar.STL</uri> -->
