<?xml version="1.0" ?>
<sdf version="1.9">
  <model name="petra_robot">
    <!-- Base Link -->
    <link name="base_link">
      <inertial>
        <mass>2.0</mass>
        <inertia>
          <ixx>0.01</ixx>
          <iyy>0.01</iyy>
          <izz>0.01</izz>
          <ixy>0.0</ixy>
          <ixz>0.0</ixz>
          <iyz>0.0</iyz>
        </inertia>
      </inertial>
      <visual name="base_visual">
        <geometry>
          <box>
            <size>0.4 0.3 0.08</size>
          </box>
        </geometry>
        <material>
          <ambient>1.0 1.0 0.0 1.0</ambient>
          <diffuse>1.0 1.0 0.0 1.0</diffuse>
        </material>
      </visual>
      <collision name="base_collision">
        <geometry>
          <box>
            <size>0.4 0.3 0.08</size>
          </box>
        </geometry>
      </collision>
    </link>

    <!-- Right Wheel -->
    <link name="right_wheel">
        <pose relative_to="base_link">0.1 -0.175 0 0 1.5708 1.5708</pose>   
      <inertial>
        <mass>1.0</mass>
        <inertia>
          <ixx>0.001</ixx>
          <iyy>0.001</iyy>
          <izz>0.001</izz>
        </inertia>
      </inertial>
      <visual name="right_wheel_visual">
        <geometry>
          <cylinder>
            <radius>0.08</radius>
            <length>0.05</length>
          </cylinder>
        </geometry>
        <material>
          <ambient>1.0 0.0 0.0 1.0</ambient>
          <diffuse>1.0 0.0 0.0 1.0</diffuse>
        </material>
      </visual>
      <collision name="right_wheel_collision">
        <geometry>
          <cylinder>
            <radius>0.08</radius>
            <length>0.05</length>
          </cylinder>
        </geometry>
      </collision>
    </link>

    <joint name="right_wheel_joint" type="revolute">
      <parent>base_link</parent>
      <child>right_wheel</child>
      <axis>
        <xyz>0 0 1</xyz>
            <limit>
                <lower>-1.79769e+308</lower>    
                <upper>1.79769e+308</upper>
            </limit>
      </axis>
    </joint>

    <!-- Left Wheel -->
    <link name="left_wheel">
      <pose relative_to="base_link">0.1 0.175 0 0 1.5708 1.5708</pose>   
      <inertial>
        <mass>1.0</mass>
        <inertia>
          <ixx>0.001</ixx>
          <iyy>0.001</iyy>
          <izz>0.001</izz>
        </inertia>
      </inertial>
      <visual name="left_wheel_visual">
        <geometry>
          <cylinder>
            <radius>0.08</radius>
            <length>0.05</length>
          </cylinder>
        </geometry>
        <material>
          <ambient>1.0 0.0 0.0 1.0</ambient>
          <diffuse>1.0 0.0 0.0 1.0</diffuse>
        </material>
      </visual>
      <collision name="left_wheel_collision">
        <geometry>
          <cylinder>
            <radius>0.08</radius>
            <length>0.05</length>
          </cylinder>
        </geometry>
      </collision>
    </link>
    <joint name="left_wheel_joint" type="revolute">
      <parent>base_link</parent>
      <child>left_wheel</child>
      <axis>
        <xyz>0 0 1</xyz>
            <limit>
                <lower>-1.79769e+308</lower>    
                <upper>1.79769e+308</upper>
            </limit>
      </axis>
    </joint>

    <!-- Caster Wheel -->
    <link name="caster_wheel_link">
        <pose relative_to="base_link">-0.1 0 -0.06 0 0 0</pose>    

      <inertial>
        <mass>0.5</mass>
        <inertia>
          <ixx>0.001</ixx>
          <iyy>0.001</iyy>
          <izz>0.001</izz>
        </inertia>
      </inertial>
      <visual name="caster_wheel_visual">
        <geometry>
          <sphere>
            <radius>0.02</radius>
          </sphere>
        </geometry>
        <material>
          <ambient>1.0 0.0 0.0 1.0</ambient>
          <diffuse>1.0 0.0 0.0 1.0</diffuse>
        </material>
      </visual>
      <collision name="caster_wheel_collision">
        <geometry>
          <sphere>
            <radius>0.02</radius>
          </sphere>
        </geometry>
      </collision>
    </link>
    <joint name="caster_wheel_joint" type="ball">
      <parent>base_link</parent>
      <child>caster_wheel_link</child>
    </joint>

    <!-- Lidar Base -->
    <link name="lidar_base_link">
        <pose relative_to="base_link">-0.1 0 0.06 0 0 0</pose>
      <inertial>
        <mass>0.5</mass>
        <inertia>
          <ixx>0.0008667</ixx>
          <iyy>0.0016</iyy>
          <izz>0.0017333</izz>
        </inertia>
      </inertial>
      <visual name="lidar_base_visual">
        <geometry>
          <box>
            <size>0.1 0.2 0.07</size>
          </box>
        </geometry>
        <material>
          <ambient>0.0 1.0 0.0 1.0</ambient>
          <diffuse>0.0 1.0 0.0 1.0</diffuse>
        </material>
      </visual>
      <collision name="lidar_base_collision">
        <geometry>
          <box>
            <size>0.2 0.2 0.07</size>
          </box>
        </geometry>
      </collision>
    </link>
    <joint name="lidar_base_joint" type="fixed">
      <parent>base_link</parent>
      <child>lidar_base_link</child>
    </joint>

    <!-- Lidar -->
    <link name="lidar_link">
      <pose relative_to="lidar_base_link">0 0 0.065 0 0 0</pose>
      <inertial>
        <mass>0.5</mass>
        <inertia>
          <ixx>0.001</ixx>
          <iyy>0.001</iyy>
          <izz>0.001</izz>
        </inertia>
      </inertial>
      <visual name="lidar_visual">
        <geometry>
          <mesh>
            <uri>meshes/2d_lidar.STL</uri> 
          </mesh>
        </geometry>
        <material>
          <ambient>0.0 0.0 0.0 1.0</ambient>
          <diffuse>0.0 0.0 0.0 1.0</diffuse>
        </material>
      </visual>
      <collision name="lidar_collision">
        <geometry>
          <mesh>
            <uri>meshes/2d_lidar.STL</uri> 
          </mesh>
        </geometry>
      </collision>
    </link> 
    <joint name="lidar_joint" type="fixed">
      <parent>lidar_base_link</parent>
      <child>lidar_link</child>
    </joint>

    <link name="camera_link">
    <pose relative_to="base_link">-0.2 0 0.03 0 0 0</pose>
      <inertial>
        <mass>0.5</mass>
        <inertia>
          <ixx>0.001</ixx>
          <iyy>0.001</iyy>
          <izz>0.001</izz>
        </inertia>
      </inertial>
      <visual name="camera_visual">
        <geometry>
            <box>
                <size>0.05 0.05 0.05 </size>
            </box>
        </geometry>
        <material>
          <ambient>0.0 0.0 0.0 1.0</ambient>
          <diffuse>0.0 0.0 0.0 1.0</diffuse>
        </material>
      </visual>
      <collision name="camera_collision">
        <geometry>
            <box>
                <size>0.1 0.1 0.1</size>
            </box>
        </geometry>
      </collision>
    </link>
    <joint name="camera_joint" type="fixed">
      <parent>base_link</parent>
      <child>camera_link</child>
    </joint>
    <model name="box1">
        <static>true</static>
        <pose>2 2 0.5 0 0 0</pose>
        <link name="link">
            <collision name="collision">
                <geometry>
                    <box>
                        <size>1 1 1</size>
                    </box>
                </geometry>
            </collision>
            <visual name="visual">
                <geometry>
                    <box>
                        <size>1 1 1</size>
                    </box>
                </geometry>
                <material>
                    <ambient>1 0 0 1</ambient>
                    <diffuse>1 0 0 1</diffuse>
                    <specular>1 0 0 1</specular>
                </material>
            </visual>
        </link>
    </model>

    <model name="cylinder1">
        <static>true</static>
        <pose>-2 -2 0.5 0 0 0</pose>
        <link name="link">
            <collision name="collision">
                <geometry>
                    <cylinder>
                        <radius>0.5</radius>
                        <length>1.0</length>
                    </cylinder>
                </geometry>
            </collision>
            <visual name="visual">
                <geometry>
                    <cylinder>
                        <radius>0.5</radius>
                        <length>1.0</length>
                    </cylinder>
                </geometry>
                <material>
                    <ambient>0 1 0 1</ambient>
                    <diffuse>0 1 0 1</diffuse>
                    <specular>0 1 0 1</specular>
                </material>
            </visual>
        </link>
    </model>

    <model name="north_wall">
        <static>true</static>
        <pose>0 5 1 0 0 0</pose>
        <link name="link">
            <collision name="collision">
                <geometry>
                    <box>
                        <size>10 0.2 2</size>
                    </box>
                </geometry>
            </collision>
            <visual name="visual">
                <geometry>
                    <box>
                        <size>10 0.2 2</size>
                    </box>
                </geometry>
                <material>
                    <ambient>0.7 0.7 0.7 1</ambient>
                    <diffuse>0.7 0.7 0.7 1</diffuse>
                    <specular>0.7 0.7 0.7 1</specular>
                </material>
            </visual>
        </link>
    </model>

    <model name="south_wall">
        <static>true</static>
        <pose>0 -5 1 0 0 0</pose>
        <link name="link">
            <collision name="collision">
                <geometry>
                    <box>
                        <size>10 0.2 2</size>
                    </box>
                </geometry>
            </collision>
            <visual name="visual">
                <geometry>
                    <box>
                        <size>10 0.2 2</size>
                    </box>
                </geometry>
                <material>
                    <ambient>0.7 0.7 0.7 1</ambient>
                    <diffuse>0.7 0.7 0.7 1</diffuse>
                    <specular>0.7 0.7 0.7 1</specular>
                </material>
            </visual>
        </link>
    </model>

    <model name="east_wall">
        <static>true</static>
        <pose>5 0 1 0 0 1.5708</pose>
        <link name="link">
            <collision name="collision">
                <geometry>
                    <box>
                        <size>10 0.2 2</size>
                    </box>
                </geometry>
            </collision>
            <visual name="visual">
                <geometry>
                    <box>
                        <size>10 0.2 2</size>
                    </box>
                </geometry>
                <material>
                    <ambient>0.7 0.7 0.7 1</ambient>
                    <diffuse>0.7 0.7 0.7 1</diffuse>
                    <specular>0.7 0.7 0.7 1</specular>
                </material>
            </visual>
        </link>
    </model>

    <model name="west_wall">
        <static>true</static>
        <pose>-5 0 1 0 0 1.5708</pose>
        <link name="link">
            <collision name="collision">
                <geometry>
                    <box>
                        <size>10 0.2 2</size>
                    </box>
                </geometry>
            </collision>
            <visual name="visual">
                <geometry>
                    <box>
                        <size>10 0.2 2</size>
                    </box>
                </geometry>
                <material>
                    <ambient>0.7 0.7 0.7 1</ambient>
                    <diffuse>0.7 0.7 0.7 1</diffuse>
                    <specular>0.7 0.7 0.7 1</specular>
                </material>
            </visual>
        </link>
    </model>
    
    <plugin filename="gz-sim-diff-drive-system" name="gz::sim::systems::DiffDrive">
        <topic>cmd_vel</topic> <!-- Topic for velocity commands to control the robot -->
        <left_joint>left_wheel_joint</left_joint> <!-- Name of the left wheel joint -->
        <right_joint>right_wheel_joint</right_joint> <!-- Name of the right wheel joint -->
        <wheel_separation>0.4</wheel_separation> <!-- Distance between the left and right wheels -->
        <wheel_radius>0.08</wheel_radius> <!-- Radius of each wheel -->
        <odom_publish_frequency>50</odom_publish_frequency> <!-- Frequency (Hz) to publish odometry data -->
        <odom_topic>/odom</odom_topic> <!-- Topic name for odometry output -->
    </plugin>
  </model>

</sdf>



            <!-- <uri>package://petra_robot/meshes/2d_lidar.STL</uri> -->
